Workbook

Sheet Cover
A1: ICICI Bank Ltd (NSE: ICICIBANK): Initiation model
A2: Equity research project. Standalone financials, Rs crore unless stated. Not investment advice.
A4: Call
A5: Rating | B5: =Valuation!B27 -> HOLD
A6: 12-month target price (Rs) | B6: =Valuation!B24 -> 1380
A7: Current price (Rs), 1-Oct-2026 | B7: =Valuation!B25 -> 1310.6
A8: Upside / (downside) | B8: =Valuation!B26 -> 0.052952846
A9: Scenario shown | B9: =Valuation!B28 -> Base
A10: Cost of equity | B10: =Inputs!B14 -> 0.1254
A12: Key financials
A13: Rs crore | B13: FY25A | C13: FY26A | D13: FY27E | E13: FY28E
A14: Net interest income | B14: =Historical!E6 -> 81165 | C14: =Historical!F6 -> 88075 | D14: =Forecast!C11 -> 99468.362 | E14: =Forecast!D11 -> 113272.7
A15: Profit after tax | B15: =Historical!E16 -> 47227 | C15: =Historical!F16 -> 50147 | D15: =Forecast!C21 -> 55256.366 | E15: =Forecast!D21 -> 62550.408
A16: EPS (Rs) | B16: =Historical!E56 -> 66.283509 | C16: =Historical!F56 -> 70.037709 | D16: =Forecast!C26 -> 77.173695 | E16: =Forecast!D26 -> 87.360904
A17: Book value per share (Rs) | B17: =Historical!E57 -> 407.02737 | C17: =Historical!F57 -> 467.44274 | D17: =Forecast!C27 -> 531.4969 | E17: =Forecast!D27 -> 604.00646
A18: RoA | B18: =Historical!E53 -> 0.023674135 | C18: =Historical!F53 -> 0.022333359 | D18: =Forecast!C37 -> 0.021665163 | E18: =Forecast!D37 -> 0.021425779
A19: RoE | B19: =Historical!E54 -> 0.17922926 | C19: =Historical!F54 -> 0.16054849 | D19: =Forecast!C38 -> 0.15451123 | E19: =Forecast!D38 -> 0.15387168
A20: Credit cost | B20: =Historical!E51 -> 0.003707586 | C20: =Historical!F51 -> 0.0037159072 | D20: =Forecast!C36 -> 0.004 | E20: =Forecast!D36 -> 0.0045
A22: How to use
A23: 1. Inputs: change blue cells. Yellow cells are the key levers (scenario selector, equity risk premium).
A24: 2. Scenario selector (Inputs) switches every driver between Bear, Base and Bull.
A25: 3. VBA: open the VBA editor (Alt+F11), File > Import File > ScenarioRunner.bas, then save as .xlsm.
A26: 4. Run the macro RunScenarios (Alt+F8) to record all three cases on Valuation, section G.
A27: Colour code: blue = hardcoded input, black = formula, green = link to another sheet.

Sheet Inputs
A1: Inputs and assumptions
A2: Blue = hardcoded input; black = formula; green = link to another sheet; yellow = key lever
A4: Market data (NSE close, 1 Oct 2026; market shut 2 Oct)
A5: Current market price (Rs) | B5: 1310.6 | D5: Yahoo Finance via yfinance, ICICIBANK.NS close 1-Oct-2026
A6: Face value per share (Rs) | B6: 2 | D6: ICICI Bank equity shares, face value Rs 2
A7: Shares outstanding (crore) | B7: =Historical!F37 -> 716 | D7: Mar-26 equity capital / face value
A8: Market capitalisation (Rs crore) | B8: =B5*B7 -> 938389.6
A10: Cost of equity (CAPM)
A11: Risk-free rate (India 10Y G-sec) | B11: 0.0715 | D11: ~7.17% on 28-Sep-2026 (Trading Economics), rounded to 7.15%
A12: Beta vs Nifty 50 | B12: 0.98 | D12: 2-year weekly log-return regression, 105 weeks to 1-Oct-2026 (computed from yfinance prices)
A13: Equity risk premium (India) | B13: 0.055 | D13: Analyst assumption; Indian sell-side practice typically 5.0% to 6.5%
A14: Cost of equity (Ke) | B14: =B11+B12*B13 -> 0.1254 | D14: Ke = Rf + Beta x ERP
A16: Scenario selector
A17: Active scenario (1 = Bear, 2 = Base, 3 = Bull) | B17: 2 | D17: Change this cell, or run the VBA macro RunScenarios to record all three
A18: Active scenario name | B18: =CHOOSE(B17,"Bear","Base","Bull") -> Base
A20: Scenario drivers
A21: Driver | B21: Year | C21: Bear | D21: Base | E21: Bull | F21: Active | G21: Rationale
A22: Advances growth | B22: FY27E | C22: 0.13 | D22: 0.16 | E22: 0.18 | F22: =CHOOSE($B$17,C22,D22,E22) -> 0.16 | G22: Q1 FY27 loans +19.6% YoY; system credit ~17.7% (RBI, Jun-26)
A23: Advances growth | B23: FY28E | C23: 0.12 | D23: 0.15 | E23: 0.17 | F23: =CHOOSE($B$17,C23,D23,E23) -> 0.15 | G23: Moderates as base grows; above nominal GDP
A24: Deposit growth | B24: FY27E | C24: 0.11 | D24: 0.14 | E24: 0.15 | F24: =CHOOSE($B$17,C24,D24,E24) -> 0.14 | G24: Q1 FY27 deposits +14.0% YoY; system ~12%
A25: Deposit growth | B25: FY28E | C25: 0.11 | D25: 0.14 | E25: 0.15 | F25: =CHOOSE($B$17,C25,D25,E25) -> 0.14 | G25: Deposit competition caps growth
A26: Total assets growth | B26: FY27E | C26: 0.12 | D26: 0.15 | E26: 0.16 | F26: =CHOOSE($B$17,C26,D26,E26) -> 0.15 | G26: Tracks blend of loan and deposit growth
A27: Total assets growth | B27: FY28E | C27: 0.11 | D27: 0.14 | E27: 0.15 | F27: =CHOOSE($B$17,C27,D27,E27) -> 0.14
A28: NII / average total assets | B28: FY27E | C28: 0.038 | D28: 0.039 | E28: 0.0398 | F28: =CHOOSE($B$17,C28,D28,E28) -> 0.039 | G28: FY26A 3.92%; Q1 FY27 NIM 4.36% stable
A29: NII / average total assets | B29: FY28E | C29: 0.0375 | D29: 0.0388 | E29: 0.0398 | F29: =CHOOSE($B$17,C29,D29,E29) -> 0.0388 | G29: Bear: deposit cost pressure
A30: Non-interest income growth | B30: FY27E | C30: 0.1 | D30: 0.14 | E30: 0.17 | F30: =CHOOSE($B$17,C30,D30,E30) -> 0.14 | G30: Q1 FY27 fees +23.5%, core non-II +16%
A31: Non-interest income growth | B31: FY28E | C31: 0.1 | D31: 0.13 | E31: 0.15 | F31: =CHOOSE($B$17,C31,D31,E31) -> 0.13
A32: Cost-to-income | B32: FY27E | C32: 0.41 | D32: 0.4 | E32: 0.39 | F32: =CHOOSE($B$17,C32,D32,E32) -> 0.4 | G32: FY26A 40.2%; branch expansion continues
A33: Cost-to-income | B33: FY28E | C33: 0.41 | D33: 0.395 | E33: 0.385 | F33: =CHOOSE($B$17,C33,D33,E33) -> 0.395 | G33: Operating leverage in base and bull
A34: Credit cost (provisions / avg advances) | B34: FY27E | C34: 0.0065 | D34: 0.004 | E34: 0.003 | F34: =CHOOSE($B$17,C34,D34,E34) -> 0.004 | G34: FY26A 0.37%; management guides under 0.50%
A35: Credit cost (provisions / avg advances) | B35: FY28E | C35: 0.007 | D35: 0.0045 | E35: 0.0035 | F35: =CHOOSE($B$17,C35,D35,E35) -> 0.0045 | G35: Bear: unsecured retail cycle turns
A36: Long-term growth (g) for justified P/B | B36: Terminal | C36: 0.095 | D36: 0.1 | E36: 0.1025 | F36: =CHOOSE($B$17,C36,D36,E36) -> 0.1 | G36: Below Ke; anchored to nominal GDP growth
A37: Holding-company discount on subsidiaries | B37: Valuation | C37: 0.25 | D37: 0.2 | E37: 0.15 | F37: =CHOOSE($B$17,C37,D37,E37) -> 0.2 | G37: Standard 15% to 30% range
A39: Fixed assumptions (all scenarios)
A40: Effective tax rate | B40: 0.245 | D40: FY26A effective rate 24.3%
A41: Dividend payout ratio | B41: 0.17 | D41: FY26 DPS Rs 12 x 716 cr shares / PAT = ~17%
A42: Treasury income FY27E-FY28E (Rs crore) | B42: 0 | D42: Not forecast: volatile and non-core
A44: Rating rule (12-month upside to target)
A45: BUY if upside at or above | B45: 0.15
A46: SELL if upside below | B46: 0
...

Sheet Historical
A1: Historical financials, standalone (Rs crore unless stated)
A2: Source: ICICI Bank audited results press releases, FY2023, FY2024, FY2026 (see Sources). Fiscal year ends 31 March.
A4: Rs crore | B4: FY22 | C4: FY23 | D4: FY24 | E4: FY25 | F4: FY26
A5: Profit and loss
A6: Net interest income | B6: 47466 | C6: 62129 | D6: 74306 | E6: 81165 | F6: 88075
A7: Non-interest income (excl. treasury) | B7: 17614 | C7: 19883 | D7: 22949 | E7: 26603 | F7: 29560
A8: of which fee income | B8: 15687 | C8: 18001 | D8: 20796 | E8: 23870 | F8: 25742
A9: Operating expenses | B9: 26733 | C9: 32873 | D9: 39133 | E9: 42372 | F9: 47234
A10: Core operating profit | B10: =B6+B7-B9 -> 38347 | C10: =C6+C7-C9 -> 49139 | D10: =D6+D7-D9 -> 58122 | E10: =E6+E7-E9 -> 65396 | F10: =F6+F7-F9 -> 70401
A11: Provisions | B11: 8641 | C11: 6666 | D11: 3643 | E11: 4683 | F11: 5380
A12: Profit before tax excl. treasury | B12: =B10-B11 -> 29706 | C12: =C10-C11 -> 42473 | D12: =D10-D11 -> 54479 | E12: =E10-E11 -> 60713 | F12: =F10-F11 -> 65021
A13: Treasury income | B13: 903 | C13: -52 | D13: 9 | E13: 1903 | F13: 1198
A14: Profit before tax | B14: =B12+B13 -> 30609 | C14: =C12+C13 -> 42421 | D14: =D12+D13 -> 54488 | E14: =E12+E13 -> 62616 | F14: =F12+F13 -> 66219
A15: Provision for taxes | B15: 7270 | C15: 10525 | D15: 13600 | E15: 15389 | F15: 16072
A16: Profit after tax | B16: =B14-B15 -> 23339 | C16: =C14-C15 -> 31896 | D16: =D14-D15 -> 40888 | E16: =E14-E15 -> 47227 | F16: =F14-F15 -> 50147
A17: Check: reported PAT | B17: 23339 | C17: 31896 | D17: 40888 | E17: 47227 | F17: 50147
A18: Check: difference (should be 0) | B18: =B16-B17 -> 0 | C18: =C16-C17 -> 0 | D18: =D16-D17 -> 0 | E18: =E16-E17 -> 0 | F18: =F16-F17 -> 0
A20: Balance sheet, 31 March
A21: Equity share capital | B21: 1390 | C21: 1397 | D21: 1405 | E21: 1425 | F21: 1432
A22: Employee stock options outstanding | B22: 266 | C22: 761 | D22: 1405 | E22: 2070 | F22: 2682
A23: Reserves and surplus | B23: 168856 | C23: 198558 | D23: 235589 | E23: 288582 | F23: 333257
A24: Deposits | B24: 1064572 | C24: 1180841 | D24: 1412825 | E24: 1610348 | F24: 1794625
A25: Borrowings (incl. subordinated debt) | B25: 107231 | C25: 119325 | D25: 124968 | E25: 123538 | F25: 124994
A26: Other liabilities and provisions | B26: 68983 | C26: 83325 | D26: 95323 | E26: 92277 | F26: 115541
A27: Total capital and liabilities | B27: =SUM(B21:B26) -> 1411298 | C27: =SUM(C21:C26) -> 1584207 | D27: =SUM(D21:D26) -> 1871515 | E27: =SUM(E21:E26) -> 2118240 | F27: =SUM(F21:F26) -> 2372531
A28: Cash and balances with RBI | B28: 109523 | C28: 68526 | D28: 89712 | E28: 119928 | F28: 121024
A29: Balances with banks, money at call | B29: 58300 | C29: 50912 | D29: 50214 | E29: 65634 | F29: 109311
A30: Investments | B30: 310241 | C30: 362330 | D30: 461942 | E30: 504757 | F30: 492217
A31: Advances | B31: 859020 | C31: 1019638 | D31: 1184406 | E31: 1341766 | F31: 1553893
A32: Fixed assets | B32: 9374 | C32: 9600 | D32: 10860 | E32: 12839 | F32: 13922
A33: Other assets | B33: 64840 | C33: 73201 | D33: 74381 | E33: 73316 | F33: 82164
A34: Total assets | B34: =SUM(B28:B33) -> 1411298 | C34: =SUM(C28:C33) -> 1584207 | D34: =SUM(D28:D33) -> 1871515 | E34: =SUM(E28:E33) -> 2118240 | F34: =SUM(F28:F33) -> 2372531
A35: Check: liabilities minus assets (should be 0) | B35: =B27-B34 -> 0 | C35: =C27-C34 -> 0 | D35: =D27-D34 -> 0 | E35: =E27-E34 -> 0 | F35: =F27-F34 -> 0
A36: Net worth (capital + reserves) | B36: =B21+B23 -> 170246 | C36: =C21+C23 -> 199955 | D36: =D21+D23 -> 236994 | E36: =E21+E23 -> 290007 | F36: =F21+F23 -> 334689
A37: Shares outstanding (crore) | B37: =B21/Inputs!$B$6 -> 695 | C37: =C21/Inputs!$B$6 -> 698.5 | D37: =D21/Inputs!$B$6 -> 702.5 | E37: =E21/Inputs!$B$6 -> 712.5 | F37: =F21/Inputs!$B$6 -> 716
A39: Asset quality (reported, 31 March)
A40: Gross NPA ratio | B40: 0.036 | C40: 0.0281 | D40: 0.0216 | E40: 0.0167 | F40: 0.014
A41: Net NPA ratio | B41: 0.0076 | C41: 0.0048 | D41: 0.0042 | E41: 0.0039 | F41: 0.0033
A42: Net interest margin (reported, full year) | C42: 0.0448 | D42: 0.0453 | E42: 0.0432 | F42: 0.0432
A44: Key ratios (computed)
...

Sheet Forecast
A1: Forecast, standalone (Rs crore unless stated)
A2: Drivers come from the Active column on Inputs. Change the scenario selector to switch cases.
A4: Rs crore | B4: FY26A | C4: FY27E | D4: FY28E | E4: Driver
A5: Balance sheet
A6: Advances | B6: =Historical!F31 -> 1553893 | C6: =B6*(1+Inputs!$F$22) -> 1802515.9 | D6: =C6*(1+Inputs!$F$23) -> 2072893.3 | E6: Prior x (1 + advances growth)
A7: Deposits | B7: =Historical!F24 -> 1794625 | C7: =B7*(1+Inputs!$F$24) -> 2045872.5 | D7: =C7*(1+Inputs!$F$25) -> 2332294.6 | E7: Prior x (1 + deposit growth)
A8: Total assets | B8: =Historical!F34 -> 2372531 | C8: =B8*(1+Inputs!$F$26) -> 2728410.6 | D8: =C8*(1+Inputs!$F$27) -> 3110388.1 | E8: Prior x (1 + asset growth)
A10: Profit and loss
A11: Net interest income | B11: =Historical!F6 -> 88075 | C11: =Inputs!$F$28*AVERAGE(B8,C8) -> 99468.362 | D11: =Inputs!$F$29*AVERAGE(C8,D8) -> 113272.7 | E11: NII / avg assets x average total assets
A12: Non-interest income (excl. treasury) | B12: =Historical!F7 -> 29560 | C12: =B12*(1+Inputs!$F$30) -> 33698.4 | D12: =C12*(1+Inputs!$F$31) -> 38079.192 | E12: Prior x (1 + growth)
A13: Core operating income | B13: =B11+B12 -> 117635 | C13: =C11+C12 -> 133166.76 | D13: =D11+D12 -> 151351.89
A14: Operating expenses | B14: =Historical!F9 -> 47234 | C14: =Inputs!$F$32*C13 -> 53266.705 | D14: =Inputs!$F$33*D13 -> 59783.996 | E14: Cost-to-income x core operating income
A15: Core operating profit | B15: =B13-B14 -> 70401 | C15: =C13-C14 -> 79900.057 | D15: =D13-D14 -> 91567.893
A16: Provisions | B16: =Historical!F11 -> 5380 | C16: =Inputs!$F$34*AVERAGE(B6,C6) -> 6712.8178 | D16: =Inputs!$F$35*AVERAGE(C6,D6) -> 8719.6706 | E16: Credit cost x average advances
A17: Profit before tax excl. treasury | B17: =B15-B16 -> 65021 | C17: =C15-C16 -> 73187.24 | D17: =D15-D16 -> 82848.222
A18: Treasury income | B18: =Historical!F13 -> 1198 | C18: =Inputs!$B$42 -> 0 | D18: =Inputs!$B$42 -> 0
A19: Profit before tax | B19: =B17+B18 -> 66219 | C19: =C17+C18 -> 73187.24 | D19: =D17+D18 -> 82848.222
A20: Provision for taxes | B20: =Historical!F15 -> 16072 | C20: =C19*Inputs!$B$40 -> 17930.874 | D20: =D19*Inputs!$B$40 -> 20297.814
A21: Profit after tax | B21: =B19-B20 -> 50147 | C21: =C19-C20 -> 55256.366 | D21: =D19-D20 -> 62550.408
A23: Equity and per share
A24: Net worth (capital + reserves) | B24: =Historical!F36 -> 334689 | C24: =B24+C21*(1-Inputs!$B$41) -> 380551.78 | D24: =C24+D21*(1-Inputs!$B$41) -> 432468.62 | E24: Prior + PAT x (1 - payout)
A25: Shares outstanding (crore) | B25: =Historical!F37 -> 716 | C25: =B25 -> 716 | D25: =C25 -> 716 | E25: Held flat (ESOP dilution ignored)
A26: EPS (Rs) | B26: =B21/B25 -> 70.037709 | C26: =C21/C25 -> 77.173695 | D26: =D21/D25 -> 87.360904
A27: Book value per share (Rs) | B27: =B24/B25 -> 467.44274 | C27: =C24/C25 -> 531.4969 | D27: =D24/D25 -> 604.00646
A28: Dividend per share (Rs) | B28: 12 | C28: =C26*Inputs!$B$41 -> 13.119528 | D28: =D26*Inputs!$B$41 -> 14.851354 | E28: FY26A: Rs 12 recommended by the Board
A30: Ratios
A31: Advances growth | B31: =Historical!F45 -> 0.15809538 | C31: =C6/B6-1 -> 0.16 | D31: =D6/C6-1 -> 0.15
A32: NII growth | B32: =Historical!F47 -> 0.085135218 | C32: =C11/B11-1 -> 0.12935977 | D32: =D11/C11-1 -> 0.13878116
A33: PAT growth | B33: =Historical!F48 -> 0.061829038 | C33: =C21/B21-1 -> 0.10188777 | D33: =D21/C21-1 -> 0.13200365
A34: NII / average total assets | B34: =Historical!F49 -> 0.03922489 | C34: =C11/AVERAGE(B8,C8) -> 0.039 | D34: =D11/AVERAGE(C8,D8) -> 0.0388
A35: Cost-to-income | B35: =Historical!F50 -> 0.40153016 | C35: =C14/C13 -> 0.4 | D35: =D14/D13 -> 0.395
A36: Credit cost | B36: =Historical!F51 -> 0.0037159072 | C36: =C16/AVERAGE(B6,C6) -> 0.004 | D36: =D16/AVERAGE(C6,D6) -> 0.0045
A37: RoA | B37: =Historical!F53 -> 0.022333359 | C37: =C21/AVERAGE(B8,C8) -> 0.021665163 | D37: =D21/AVERAGE(C8,D8) -> 0.021425779
A38: RoE | B38: =Historical!F54 -> 0.16054849 | C38: =C21/AVERAGE(B24,C24) -> 0.15451123 | D38: =D21/AVERAGE(C24,D24) -> 0.15387168
A39: Credit-deposit ratio | B39: =Historical!F55 -> 0.86585944 | C39: =C6/C7 -> 0.88104996 | D39: =D6/D7 -> 0.88877847
A41: Valuation at current price (standalone book)
A42: P/E at CMP (x) | B42: =Inputs!$B$5/B26 -> 18.712776 | C42: =Inputs!$B$5/C26 -> 16.98247 | D42: =Inputs!$B$5/D26 -> 15.002134
A43: P/B at CMP (x) | B43: =Inputs!$B$5/B27 -> 2.8037659 | C43: =Inputs!$B$5/C27 -> 2.4658657 | D43: =Inputs!$B$5/D27 -> 2.1698444
A44: Note: CMP includes the value of listed subsidiaries, so these multiples overstate the standalone bank's multiple. See Valuation.

Sheet Valuation
A1: Valuation: justified P/B on the standalone bank + listed subsidiaries (SOTP)
A2: 12-month target. Standalone bank valued on Sep-27E book (average of FY27E and FY28E).
A4: A. Standalone bank: justified P/B = (RoE - g) / (Ke - g)
A5: Cost of equity (Ke) | B5: =Inputs!$B$14 -> 0.1254
A6: Long-term growth (g) | B6: =Inputs!$F$36 -> 0.1
A7: Sustainable RoE (average FY27E-FY28E) | B7: =AVERAGE(Forecast!C38,Forecast!D38) -> 0.15419145
A8: Justified P/B (x) | B8: =IF(B5>B6,(B7-B6)/(B5-B6),NA()) -> 2.1335218 | C8: Gordon growth form; valid only when Ke > g
A9: BVPS FY27E (Rs) | B9: =Forecast!C27 -> 531.4969
A10: BVPS FY28E (Rs) | B10: =Forecast!D27 -> 604.00646
A11: BVPS Sep-27E (Rs) | B11: =AVERAGE(B9,B10) -> 567.75168
A12: Standalone bank value per share (Rs) | B12: =B8*B11 -> 1211.3106
A14: B. Listed subsidiaries at market value, less holding-company discount
A15: Subsidiary | B15: Mkt cap (Rs cr) | C15: ICICI stake | D15: Attributable (Rs cr) | E15: Discount | F15: Post-discount (Rs cr) | G15: Per ICICI share (Rs)
A16: ICICI Prudential AMC (ICICIAMC) | B16: 152133 | C16: 0.53 | D16: =B16*C16 -> 80630.49 | E16: =Inputs!$F$37 -> 0.2 | F16: =D16*(1-E16) -> 64504.392 | G16: =F16/Inputs!$B$7 -> 90.089933
A17: ICICI Lombard General (ICICIGI) | B17: 78090 | C17: 0.51 | D17: =B17*C17 -> 39825.9 | E17: =Inputs!$F$37 -> 0.2 | F17: =D17*(1-E17) -> 31860.72 | G17: =F17/Inputs!$B$7 -> 44.498212
A18: ICICI Prudential Life (ICICIPRULI) | B18: 65002 | C18: 0.528 | D18: =B18*C18 -> 34321.056 | E18: =Inputs!$F$37 -> 0.2 | F18: =D18*(1-E18) -> 27456.845 | G18: =F18/Inputs!$B$7 -> 38.347549
A19: Subsidiaries total | D19: =SUM(D16:D18) -> 154777.45 | F19: =SUM(F16:F18) -> 123821.96 | G19: =SUM(G16:G18) -> 172.93569
A20: Market caps: Yahoo Finance via yfinance, 1-Oct-2026. Unlisted subsidiaries (ICICI Home Finance and others) excluded: conservative.
A22: C. Target price and rating
A23: Standalone + subsidiaries (Rs) | B23: =B12+G19 -> 1384.2463
A24: 12-month target price (Rs, rounded to 10) | B24: =ROUND(B23,-1) -> 1380
A25: Current market price (Rs) | B25: =Inputs!$B$5 -> 1310.6
A26: Upside / (downside) | B26: =B24/B25-1 -> 0.052952846
A27: Rating | B27: =IF(B26>=Inputs!$B$45,"BUY",IF(B26<Inputs!$B$46,"SELL","HOLD")) -> HOLD
A28: Scenario shown | B28: =Inputs!$B$18 -> Base
A30: D. What the current price implies (reverse valuation)
A31: Implied standalone P/B on Sep-27E book (x) | B31: =(B25-G19)/B11 -> 2.0038061
A32: Implied long-term growth at model RoE and Ke | B32: =(B7-B31*B5)/(1-B31) -> 0.096717715 | C32: Solves P/B = (RoE - g)/(Ke - g) for g
A34: E. Sensitivity: target price (Rs) to sustainable RoE (rows) and Ke (columns), g held at active
A35: RoE \ Ke | B35: 0.115 | C35: 0.12 | D35: 0.125 | E35: 0.13 | F35: 0.135
A36: 0.14 | B36: =IF(B$35>$B$6,ROUND(($A36-$B$6)/(B$35-$B$6)*$B$11+$G$19,-1),NA()) -> 1690 | C36: =IF(C$35>$B$6,ROUND(($A36-$B$6)/(C$35-$B$6)*$B$11+$G$19,-1),NA()) -> 1310 | D36: =IF(D$35>$B$6,ROUND(($A36-$B$6)/(D$35-$B$6)*$B$11+$G$19,-1),NA()) -> 1080 | E36: =IF(E$35>$B$6,ROUND(($A36-$B$6)/(E$35-$B$6)*$B$11+$G$19,-1),NA()) -> 930 | F36: =IF(F$35>$B$6,ROUND(($A36-$B$6)/(F$35-$B$6)*$B$11+$G$19,-1),NA()) -> 820
A37: 0.15 | B37: =IF(B$35>$B$6,ROUND(($A37-$B$6)/(B$35-$B$6)*$B$11+$G$19,-1),NA()) -> 2070 | C37: =IF(C$35>$B$6,ROUND(($A37-$B$6)/(C$35-$B$6)*$B$11+$G$19,-1),NA()) -> 1590 | D37: =IF(D$35>$B$6,ROUND(($A37-$B$6)/(D$35-$B$6)*$B$11+$G$19,-1),NA()) -> 1310 | E37: =IF(E$35>$B$6,ROUND(($A37-$B$6)/(E$35-$B$6)*$B$11+$G$19,-1),NA()) -> 1120 | F37: =IF(F$35>$B$6,ROUND(($A37-$B$6)/(F$35-$B$6)*$B$11+$G$19,-1),NA()) -> 980
A38: 0.16 | B38: =IF(B$35>$B$6,ROUND(($A38-$B$6)/(B$35-$B$6)*$B$11+$G$19,-1),NA()) -> 2440 | C38: =IF(C$35>$B$6,ROUND(($A38-$B$6)/(C$35-$B$6)*$B$11+$G$19,-1),NA()) -> 1880 | D38: =IF(D$35>$B$6,ROUND(($A38-$B$6)/(D$35-$B$6)*$B$11+$G$19,-1),NA()) -> 1540 | E38: =IF(E$35>$B$6,ROUND(($A38-$B$6)/(E$35-$B$6)*$B$11+$G$19,-1),NA()) -> 1310 | F38: =IF(F$35>$B$6,ROUND(($A38-$B$6)/(F$35-$B$6)*$B$11+$G$19,-1),NA()) -> 1150
A39: 0.17 | B39: =IF(B$35>$B$6,ROUND(($A39-$B$6)/(B$35-$B$6)*$B$11+$G$19,-1),NA()) -> 2820 | C39: =IF(C$35>$B$6,ROUND(($A39-$B$6)/(C$35-$B$6)*$B$11+$G$19,-1),NA()) -> 2160 | D39: =IF(D$35>$B$6,ROUND(($A39-$B$6)/(D$35-$B$6)*$B$11+$G$19,-1),NA()) -> 1760 | E39: =IF(E$35>$B$6,ROUND(($A39-$B$6)/(E$35-$B$6)*$B$11+$G$19,-1),NA()) -> 1500 | F39: =IF(F$35>$B$6,ROUND(($A39-$B$6)/(F$35-$B$6)*$B$11+$G$19,-1),NA()) -> 1310
A40: 0.18 | B40: =IF(B$35>$B$6,ROUND(($A40-$B$6)/(B$35-$B$6)*$B$11+$G$19,-1),NA()) -> 3200 | C40: =IF(C$35>$B$6,ROUND(($A40-$B$6)/(C$35-$B$6)*$B$11+$G$19,-1),NA()) -> 2440 | D40: =IF(D$35>$B$6,ROUND(($A40-$B$6)/(D$35-$B$6)*$B$11+$G$19,-1),NA()) -> 1990 | E40: =IF(E$35>$B$6,ROUND(($A40-$B$6)/(E$35-$B$6)*$B$11+$G$19,-1),NA()) -> 1690 | F40: =IF(F$35>$B$6,ROUND(($A40-$B$6)/(F$35-$B$6)*$B$11+$G$19,-1),NA()) -> 1470
A42: F. Sensitivity: target price (Rs) to long-term growth g (rows) and Ke (columns), RoE held at model
A43: g \ Ke | B43: 0.115 | C43: 0.12 | D43: 0.125 | E43: 0.13 | F43: 0.135
A44: 0.085 | B44: =IF(B$43>$A44,ROUND(($B$7-$A44)/(B$43-$A44)*$B$11+$G$19,-1),NA()) -> 1480 | C44: =IF(C$43>$A44,ROUND(($B$7-$A44)/(C$43-$A44)*$B$11+$G$19,-1),NA()) -> 1300 | D44: =IF(D$43>$A44,ROUND(($B$7-$A44)/(D$43-$A44)*$B$11+$G$19,-1),NA()) -> 1160 | E44: =IF(E$43>$A44,ROUND(($B$7-$A44)/(E$43-$A44)*$B$11+$G$19,-1),NA()) -> 1050 | F44: =IF(F$43>$A44,ROUND(($B$7-$A44)/(F$43-$A44)*$B$11+$G$19,-1),NA()) -> 960
A45: 0.09 | B45: =IF(B$43>$A45,ROUND(($B$7-$A45)/(B$43-$A45)*$B$11+$G$19,-1),NA()) -> 1630 | C45: =IF(C$43>$A45,ROUND(($B$7-$A45)/(C$43-$A45)*$B$11+$G$19,-1),NA()) -> 1390 | D45: =IF(D$43>$A45,ROUND(($B$7-$A45)/(D$43-$A45)*$B$11+$G$19,-1),NA()) -> 1210 | E45: =IF(E$43>$A45,ROUND(($B$7-$A45)/(E$43-$A45)*$B$11+$G$19,-1),NA()) -> 1080 | F45: =IF(F$43>$A45,ROUND(($B$7-$A45)/(F$43-$A45)*$B$11+$G$19,-1),NA()) -> 980
A46: 0.095 | B46: =IF(B$43>$A46,ROUND(($B$7-$A46)/(B$43-$A46)*$B$11+$G$19,-1),NA()) -> 1850 | C46: =IF(C$43>$A46,ROUND(($B$7-$A46)/(C$43-$A46)*$B$11+$G$19,-1),NA()) -> 1520 | D46: =IF(D$43>$A46,ROUND(($B$7-$A46)/(D$43-$A46)*$B$11+$G$19,-1),NA()) -> 1290 | E46: =IF(E$43>$A46,ROUND(($B$7-$A46)/(E$43-$A46)*$B$11+$G$19,-1),NA()) -> 1130 | F46: =IF(F$43>$A46,ROUND(($B$7-$A46)/(F$43-$A46)*$B$11+$G$19,-1),NA()) -> 1010
...

Sheet Peers
A1: Peer comparison: large Indian banks
A2: Yahoo Finance via yfinance, NSE close 1-Oct-2026. P/B and RoE are trailing, consolidated, as computed by the data provider.
A4: Bank | B4: NSE ticker | C4: Price (Rs) | D4: P/B (x) | E4: RoE (trailing) | F4: Market cap (Rs cr) | G4: P/B per 1pt of RoE
A5: ICICI Bank | B5: ICICIBANK | C5: 1310.6 | D5: 2.4711 | E5: 0.1607 | F5: 940802 | G5: =D5/(E5*100) -> 0.153771
A6: HDFC Bank | B6: HDFCBANK | C6: 721.2 | D6: 1.8313 | E6: 0.1384 | F6: 1111981 | G6: =D6/(E6*100) -> 0.13231936
A7: Kotak Mahindra Bank | B7: KOTAKBANK | C7: 418.35 | D7: 2.2961 | F7: 416170
A8: Axis Bank | B8: AXISBANK | C8: 1217.1 | D8: 1.6962 | E8: 0.1335 | F8: 378967 | G8: =D8/(E8*100) -> 0.12705618
A9: State Bank of India | B9: SBIN | C9: 954.1 | D9: 1.416 | E9: 0.1518 | F9: 880693 | G9: =D9/(E9*100) -> 0.093280632
A10: Peer median (excl. ICICI) | D10: =MEDIAN(D6:D9) -> 1.76375 | E10: =MEDIAN(E6:E9) -> 0.1384 | G10: =MEDIAN(G6:G9) -> 0.12705618
A11: ICICI premium / (discount) to peer median P/B | D11: =D5/D10-1 -> 0.4010489
A12: ICICI RoE gap vs peer median (percentage points) | E12: =(E5-E10)*100 -> 2.23
A14: Reading: ICICI trades at the highest P/B in the group. Its RoE lead explains part of the premium; its listed subsidiaries explain more. Provider data are consolidated, so these differ from the standalone multiples on Forecast.

Sheet Sources
A1: Sources
A3: Data | B3: Source | C3: Link
A4: FY2026 and FY2025 P&L and balance sheet (audited) | B4: ICICI Bank press release, 18-Apr-2026 | C4: https://www.icici.bank.in/about-us/news-room/2026/performance-review-quarter-ended-march-31-2026
A5: FY2024 and FY2023 P&L and balance sheet (audited) | B5: ICICI Bank press release, 27-Apr-2024 | C5: https://www.icici.bank.in/about-us/article/performance-review-quarter-ended-march-31-2024
A6: FY2022 P&L and Mar-22 balance sheet (audited) | B6: ICICI Bank press release, Apr-2023 | C6: https://www.icici.bank.in/about-us/news-room/2023/performance-review-quarter-ended-march-thirty-one-two-zero-two-three
A7: Q1 FY27 standalone results | B7: Capital Market via JM Financial, 18/20-Jul-2026 | C7: https://www.jmfinancialservices.in/market-news-and-insights/1711332
A8: Q1 FY27 earnings call highlights | B8: MarketBeat, 18-Jul-2026 | C8: https://www.marketbeat.com/instant-alerts/icici-bank-q1-earnings-call-highlights-2026-07-18/
A9: Share prices, beta inputs, peer P/B and RoE, subsidiary market caps | B9: Yahoo Finance via yfinance, 1-Oct-2026 close | C9: https://finance.yahoo.com/quote/ICICIBANK.NS
A10: India 10Y G-sec yield | B10: Trading Economics, 28-Sep-2026 | C10: https://tradingeconomics.com/india/government-bond-yield/news/587153
A11: RBI repo rate 5.25%, August 2026 MPC minutes | B11: RBI MPC minutes, 3-5 Aug 2026 | C11: https://hellobanker.in/minutes-of-the-rbi-monetary-policy-committee-meeting-held-from-august-3-to-5-2026/
A12: System credit and deposit growth | B12: RBI weekly statistical supplement, Jun-2026 | C12: https://rbi.org.in/scriptS/BS_PressReleaseDisplay.aspx?prid=63031
A13: ICICI stake in ICICI Prudential Life (~52.8%) | B13: Upstox, 2-Sep-2026 | C13: https://upstox.com/news/market-news/stocks/icici-bank-shares-in-focus-on-completing-acquisition-of-2-stake-in-icici-prudential-life-for-1-470-crore-all-you-need-to-know/article-199699/
A14: ICICI stake in ICICI Prudential AMC (51% pre-FY26 purchase) | B14: Business Standard, Dec-2025 | C14: https://www.business-standard.com/markets/capital-market-news/icici-bank-says-icici-prudential-amc-files-rhp-for-ipo-125120600153_1.html
